<?xml version="1.0" encoding="utf-8"?>
<!-- This URDF was automatically created by SolidWorks to URDF Exporter! Originally created by Stephen Brawner (brawner@gmail.com) 
     Commit Version: 1.6.0-1-g15f4949  Build Version: 1.6.7594.29634
     For more information, please see http://wiki.ros.org/sw_urdf_exporter -->
<robot
  name="FollowerTransportMech">
  <link
    name="Base_Link">
    <inertial>
      <origin
        xyz="-1.5124E-05 5.6925E-17 0.018896"
        rpy="0 0 0" />
      <mass
        value="7.6794" />
      <inertia
        ixx="0.074281"
        ixy="2.5898E-19"
        ixz="-2.5858E-20"
        iyy="0.074269"
        iyz="5.7099E-21"
        izz="0.13323" />
    </inertial>
    <visual>
      <origin
        xyz="0 0 0"
        rpy="0 0 0" />
      <geometry>
        <mesh
          filename="package://FollowerTransportMech/meshes/Base_Link.STL" />
      </geometry>
      <material
        name="">
        <color
          rgba="0.89804 0.91765 0.92941 1" />
      </material>
    </visual>
    <collision>
      <origin
        xyz="0 0 0"
        rpy="0 0 0" />
      <geometry>
        <mesh
          filename="package://FollowerTransportMech/meshes/Base_Link.STL" />
      </geometry>
    </collision>
  </link>
  <link
    name="Link1">
    <inertial>
      <origin
        xyz="-0.031049 1.5053E-18 0.0057292"
        rpy="0 0 0" />
      <mass
        value="2.3714" />
      <inertia
        ixx="0.017705"
        ixy="2.7029E-19"
        ixz="1.1405E-21"
        iyy="0.017693"
        iyz="-4.3582E-23"
        izz="0.035349" />
    </inertial>
    <visual>
      <origin
        xyz="0 0 0"
        rpy="0 0 0" />
      <geometry>
        <mesh
          filename="package://FollowerTransportMech/meshes/Link1.STL" />
      </geometry>
      <material
        name="">
        <color
          rgba="0.89804 0.91765 0.92941 1" />
      </material>
    </visual>
    <collision>
      <origin
        xyz="0 0 0"
        rpy="0 0 0" />
      <geometry>
        <mesh
          filename="package://FollowerTransportMech/meshes/Link1.STL" />
      </geometry>
    </collision>
  </link>
  <joint
    name="Joint1"
    type="fixed">
    <origin
      xyz="0 0 0.3"
      rpy="0 0 0" />
    <parent
      link="Base_Link" />
    <child
      link="Link1" />
    <axis
      xyz="0 0 0" />
  </joint>
  <link
    name="Link2">
    <inertial>
      <origin
        xyz="2.6747E-06 3.9417E-07 0.002683"
        rpy="0 0 0" />
      <mass
        value="0.13629" />
      <inertia
        ixx="0.00024629"
        ixy="3.2485E-20"
        ixz="5.8377E-22"
        iyy="0.00024629"
        iyz="7.7047E-22"
        izz="0.00048984" />
    </inertial>
    <visual>
      <origin
        xyz="0 0 0"
        rpy="0 0 0" />
      <geometry>
        <mesh
          filename="package://FollowerTransportMech/meshes/Link2.STL" />
      </geometry>
      <material
        name="">
        <color
          rgba="0.89804 0.91765 0.92941 1" />
      </material>
    </visual>
    <collision>
      <origin
        xyz="0 0 0"
        rpy="0 0 0" />
      <geometry>
        <mesh
          filename="package://FollowerTransportMech/meshes/Link2.STL" />
      </geometry>
    </collision>
  </link>
  <joint
    name="Joint2"
    type="fixed">
    <origin
      xyz="0.10525 0 0.025"
      rpy="0 0 0" />
    <parent
      link="Link1" />
    <child
      link="Link2" />
    <axis
      xyz="0 0 0" />
  </joint>
  <link
    name="Link3">
    <inertial>
      <origin
        xyz="0.020099 3.7557E-15 -0.0047053"
        rpy="0 0 0" />
      <mass
        value="0.51766" />
      <inertia
        ixx="0.00017227"
        ixy="-3.1973E-17"
        ixz="-2.0124E-18"
        iyy="0.0018071"
        iyz="-4.2362E-21"
        izz="0.0019734" />
    </inertial>
    <visual>
      <origin
        xyz="0 0 0"
        rpy="0 0 0" />
      <geometry>
        <mesh
          filename="package://FollowerTransportMech/meshes/Link3.STL" />
      </geometry>
      <material
        name="">
        <color
          rgba="0.89804 0.91765 0.92941 1" />
      </material>
    </visual>
    <collision>
      <origin
        xyz="0 0 0"
        rpy="0 0 0" />
      <geometry>
        <mesh
          filename="package://FollowerTransportMech/meshes/Link3.STL" />
      </geometry>
    </collision>
  </link>
  <joint
    name="DiscToSlide"
    type="revolute">
    <origin
      xyz="0 0 0.017"
      rpy="0 0 0" />
    <parent
      link="Link2" />
    <child
      link="Link3" />
    <axis
      xyz="0 0 1" />
    <limit
      lower="-3.1416"
      upper="3.1416"
      effort="0"
      velocity="0" />
  </joint>
  <link
    name="Link4Slider">
    <inertial>
      <origin
        xyz="1.6653E-16 1.2924E-15 0.0057417"
        rpy="0 0 0" />
      <mass
        value="0.28597" />
      <inertia
        ixx="0.00027211"
        ixy="3.0917E-20"
        ixz="-3.9445E-20"
        iyy="0.00016554"
        iyz="-5.4517E-20"
        izz="0.00039835" />
    </inertial>
    <visual>
      <origin
        xyz="0 0 0"
        rpy="0 0 0" />
      <geometry>
        <mesh
          filename="package://FollowerTransportMech/meshes/Link4Slider.STL" />
      </geometry>
      <material
        name="">
        <color
          rgba="0.89804 0.91765 0.92941 1" />
      </material>
    </visual>
    <collision>
      <origin
        xyz="0 0 0"
        rpy="0 0 0" />
      <geometry>
        <mesh
          filename="package://FollowerTransportMech/meshes/Link4Slider.STL" />
      </geometry>
    </collision>
  </link>
  <joint
    name="SlideToSlider"
    type="prismatic">
    <origin
      xyz="0 0 0.003"
      rpy="0 0 0" />
    <parent
      link="Link3" />
    <child
      link="Link4Slider" />
    <axis
      xyz="1 0 0" />
    <limit
      lower="-0.08"
      upper="0.08"
      effort="0"
      velocity="0" />
  </joint>
</robot>
