<?xml version="1.0" encoding="utf-8"?>
<!-- This URDF was automatically created by SolidWorks to URDF Exporter! Originally created by Stephen Brawner (brawner@gmail.com) 
     Commit Version: 1.6.0-1-g15f4949  Build Version: 1.6.7594.29634
     For more information, please see http://wiki.ros.org/sw_urdf_exporter -->
<robot
  name="LeaderTransportMech">
  <link
    name="Base_Link">
    <inertial>
      <origin
        xyz="-0.022996 0.00012926 0.01905"
        rpy="0 0 0" />
      <mass
        value="8.9035" />
      <inertia
        ixx="0.074512"
        ixy="9.191E-19"
        ixz="5.6264E-21"
        iyy="0.074483"
        iyz="-1.0896E-23"
        izz="0.13359" />
    </inertial>
    <visual>
      <origin
        xyz="0 0 0"
        rpy="0 0 0" />
      <geometry>
        <mesh
          filename="package://LeaderTransportMech/meshes/Base_Link.STL" />
      </geometry>
      <material
        name="">
        <color
          rgba="0.89804 0.91765 0.92941 1" />
      </material>
    </visual>
    <collision>
      <origin
        xyz="0 0 0"
        rpy="0 0 0" />
      <geometry>
        <mesh
          filename="package://LeaderTransportMech/meshes/Base_Link.STL" />
      </geometry>
    </collision>
  </link>
  <link
    name="Link1">
    <inertial>
      <origin
        xyz="9.2602E-06 1.8618E-19 0.0025"
        rpy="0 0 0" />
      <mass
        value="1.7577" />
      <inertia
        ixx="0.017586"
        ixy="4.9353E-19"
        ixz="-7.4255E-23"
        iyy="0.017558"
        iyz="-8.9751E-24"
        izz="0.035137" />
    </inertial>
    <visual>
      <origin
        xyz="0 0 0"
        rpy="0 0 0" />
      <geometry>
        <mesh
          filename="package://LeaderTransportMech/meshes/Link1.STL" />
      </geometry>
      <material
        name="">
        <color
          rgba="0.89804 0.91765 0.92941 1" />
      </material>
    </visual>
    <collision>
      <origin
        xyz="0 0 0"
        rpy="0 0 0" />
      <geometry>
        <mesh
          filename="package://LeaderTransportMech/meshes/Link1.STL" />
      </geometry>
    </collision>
  </link>
  <joint
    name="Joint1"
    type="fixed">
    <origin
      xyz="0 0 0.3"
      rpy="0 0 0" />
    <parent
      link="Base_Link" />
    <child
      link="Link1" />
    <axis
      xyz="0 0 0" />
  </joint>
  <link
    name="Link2">
    <inertial>
      <origin
        xyz="-1.3878E-17 2.4286E-17 0.002683"
        rpy="0 0 0" />
      <mass
        value="0.13629" />
      <inertia
        ixx="0.00024629"
        ixy="-3.8877E-20"
        ixz="2.7121E-21"
        iyy="0.00024629"
        iyz="1.5445E-21"
        izz="0.00048984" />
    </inertial>
    <visual>
      <origin
        xyz="0 0 0"
        rpy="0 0 0" />
      <geometry>
        <mesh
          filename="package://LeaderTransportMech/meshes/Link2.STL" />
      </geometry>
      <material
        name="">
        <color
          rgba="0.89804 0.91765 0.92941 1" />
      </material>
    </visual>
    <collision>
      <origin
        xyz="0 0 0"
        rpy="0 0 0" />
      <geometry>
        <mesh
          filename="package://LeaderTransportMech/meshes/Link2.STL" />
      </geometry>
    </collision>
  </link>
  <joint
    name="Joint2"
    type="fixed">
    <origin
      xyz="0.1056 0.00033934 0.025"
      rpy="0 0 0" />
    <parent
      link="Link1" />
    <child
      link="Link2" />
    <axis
      xyz="0 0 0" />
  </joint>
  <link
    name="Link3">
    <inertial>
      <origin
        xyz="2.9143E-16 1.0647E-15 -0.003698"
        rpy="0 0 0" />
      <mass
        value="0.375" />
      <inertia
        ixx="0.00046566"
        ixy="1.7736E-21"
        ixz="8.5501E-20"
        iyy="0.00046566"
        iyz="-1.2164E-19"
        izz="0.00086824" />
    </inertial>
    <visual>
      <origin
        xyz="0 0 0"
        rpy="0 0 0" />
      <geometry>
        <mesh
          filename="package://LeaderTransportMech/meshes/Link3.STL" />
      </geometry>
      <material
        name="">
        <color
          rgba="0.89804 0.91765 0.92941 1" />
      </material>
    </visual>
    <collision>
      <origin
        xyz="0 0 0"
        rpy="0 0 0" />
      <geometry>
        <mesh
          filename="package://LeaderTransportMech/meshes/Link3.STL" />
      </geometry>
    </collision>
  </link>
  <joint
    name="FrontBlock"
    type="revolute">
    <origin
      xyz="0 0 0.025"
      rpy="0 0 0" />
    <parent
      link="Link2" />
    <child
      link="Link3" />
    <axis
      xyz="0 0 1" />
    <limit
      lower="-3.1416"
      upper="3.1416"
      effort="0"
      velocity="0" />
  </joint>
</robot>